Workbook

Sheet Reporting
A1: Compliance reporting and case backlog
A3: FICTIONAL DATA / 29 Jun - 20 Sep 2026 / Prepared by Erochukwu Amajoyi
A4: Cutoff (exclusive) | B4: 46286 | C4: Midnight UTC. Snapshot includes all activity before this timestamp.
A6: Total cases | C6: Open backlog | E6: Overdue open | G6: On-time due cohort
A7: =COUNTIF(Cases!$E$6:$E$1205,"<"&$B$4) -> 1200 | C7: =SUM(Cases!$I$6:$I$1205) -> 266 | E7: =SUM(Cases!$J$6:$J$1205) -> 157 | G7: =IF(SUM(Cases!$K$6:$K$1205)=0,"n.a.",SUM(Cases!$L$6:$L$1205)/SUM(Cases!$K$6:$K$1205)) -> 0.33921933
A10: ="Due cohort: "&SUM(Cases!$L$6:$L$1205)&" on time / "&SUM(Cases!$K$6:$K$1205)&" due. Open due cases remain in the denominator. Mean resolution: "&TEXT(AVERAGE(Cases!$N$6:$N$1205),"0.0")&" days across "&SUM(Cases!$M$6:$M$1205)&" closed cases. Illustrative data, not Wren results." -> Due cohort: 365 on time / 1076 due. Open due cases remain in the denominator. Mean resolution: 10.2 days across 934 closed cases. Illustrative data, not Wren results.
A13: Department | B13: Cases | C13: Open | D13: Overdue
A14: Customer Services | B14: =COUNTIFS(Cases!$B$6:$B$1205,A14,Cases!$E$6:$E$1205,"<"&$B$4) -> 500 | C14: =SUMIFS(Cases!$I$6:$I$1205,Cases!$B$6:$B$1205,A14) -> 88 | D14: =SUMIFS(Cases!$J$6:$J$1205,Cases!$B$6:$B$1205,A14) -> 49
A15: Warehouse | B15: =COUNTIFS(Cases!$B$6:$B$1205,A15,Cases!$E$6:$E$1205,"<"&$B$4) -> 341 | C15: =SUMIFS(Cases!$I$6:$I$1205,Cases!$B$6:$B$1205,A15) -> 99 | D15: =SUMIFS(Cases!$J$6:$J$1205,Cases!$B$6:$B$1205,A15) -> 56
A16: Installation | B16: =COUNTIFS(Cases!$B$6:$B$1205,A16,Cases!$E$6:$E$1205,"<"&$B$4) -> 359 | C16: =SUMIFS(Cases!$I$6:$I$1205,Cases!$B$6:$B$1205,A16) -> 79 | D16: =SUMIFS(Cases!$J$6:$J$1205,Cases!$B$6:$B$1205,A16) -> 52
A17: Total | B17: =SUM(B14:B16) -> 1200 | C17: =SUM(C14:C16) -> 266 | D17: =SUM(D14:D16) -> 157
A19: Review the oldest overdue cases first; compare workload and resolution by department before changing targets. The fixture intentionally slows some Warehouse cases; this is not a causal finding.
A23: Week starting | B23: Opened | C23: Closed | D23: Closing backlog
A24: 46202 | B24: =COUNTIFS(Cases!$E$6:$E$1205,">="&A24,Cases!$E$6:$E$1205,"<"&A24+7) -> 97 | C24: =COUNTIFS(Cases!$G$6:$G$1205,">="&A24,Cases!$G$6:$G$1205,"<"&A24+7) -> 15 | D24: =COUNTIF(Cases!$E$6:$E$1205,"<"&A24+7)-COUNTIFS(Cases!$G$6:$G$1205,">=1",Cases!$G$6:$G$1205,"<"&A24+7) -> 82
A25: 46209 | B25: =COUNTIFS(Cases!$E$6:$E$1205,">="&A25,Cases!$E$6:$E$1205,"<"&A25+7) -> 94 | C25: =COUNTIFS(Cases!$G$6:$G$1205,">="&A25,Cases!$G$6:$G$1205,"<"&A25+7) -> 41 | D25: =COUNTIF(Cases!$E$6:$E$1205,"<"&A25+7)-COUNTIFS(Cases!$G$6:$G$1205,">=1",Cases!$G$6:$G$1205,"<"&A25+7) -> 135
A26: 46216 | B26: =COUNTIFS(Cases!$E$6:$E$1205,">="&A26,Cases!$E$6:$E$1205,"<"&A26+7) -> 106 | C26: =COUNTIFS(Cases!$G$6:$G$1205,">="&A26,Cases!$G$6:$G$1205,"<"&A26+7) -> 94 | D26: =COUNTIF(Cases!$E$6:$E$1205,"<"&A26+7)-COUNTIFS(Cases!$G$6:$G$1205,">=1",Cases!$G$6:$G$1205,"<"&A26+7) -> 147
A27: 46223 | B27: =COUNTIFS(Cases!$E$6:$E$1205,">="&A27,Cases!$E$6:$E$1205,"<"&A27+7) -> 112 | C27: =COUNTIFS(Cases!$G$6:$G$1205,">="&A27,Cases!$G$6:$G$1205,"<"&A27+7) -> 103 | D27: =COUNTIF(Cases!$E$6:$E$1205,"<"&A27+7)-COUNTIFS(Cases!$G$6:$G$1205,">=1",Cases!$G$6:$G$1205,"<"&A27+7) -> 156
A28: 46230 | B28: =COUNTIFS(Cases!$E$6:$E$1205,">="&A28,Cases!$E$6:$E$1205,"<"&A28+7) -> 111 | C28: =COUNTIFS(Cases!$G$6:$G$1205,">="&A28,Cases!$G$6:$G$1205,"<"&A28+7) -> 87 | D28: =COUNTIF(Cases!$E$6:$E$1205,"<"&A28+7)-COUNTIFS(Cases!$G$6:$G$1205,">=1",Cases!$G$6:$G$1205,"<"&A28+7) -> 180
A29: 46237 | B29: =COUNTIFS(Cases!$E$6:$E$1205,">="&A29,Cases!$E$6:$E$1205,"<"&A29+7) -> 100 | C29: =COUNTIFS(Cases!$G$6:$G$1205,">="&A29,Cases!$G$6:$G$1205,"<"&A29+7) -> 109 | D29: =COUNTIF(Cases!$E$6:$E$1205,"<"&A29+7)-COUNTIFS(Cases!$G$6:$G$1205,">=1",Cases!$G$6:$G$1205,"<"&A29+7) -> 171
A30: 46244 | B30: =COUNTIFS(Cases!$E$6:$E$1205,">="&A30,Cases!$E$6:$E$1205,"<"&A30+7) -> 94 | C30: =COUNTIFS(Cases!$G$6:$G$1205,">="&A30,Cases!$G$6:$G$1205,"<"&A30+7) -> 95 | D30: =COUNTIF(Cases!$E$6:$E$1205,"<"&A30+7)-COUNTIFS(Cases!$G$6:$G$1205,">=1",Cases!$G$6:$G$1205,"<"&A30+7) -> 170
A31: 46251 | B31: =COUNTIFS(Cases!$E$6:$E$1205,">="&A31,Cases!$E$6:$E$1205,"<"&A31+7) -> 105 | C31: =COUNTIFS(Cases!$G$6:$G$1205,">="&A31,Cases!$G$6:$G$1205,"<"&A31+7) -> 67 | D31: =COUNTIF(Cases!$E$6:$E$1205,"<"&A31+7)-COUNTIFS(Cases!$G$6:$G$1205,">=1",Cases!$G$6:$G$1205,"<"&A31+7) -> 208 | E31: Backlog is a point-in-time stock. Do not sum weekly or monthly backlog balances.
A32: 46258 | B32: =COUNTIFS(Cases!$E$6:$E$1205,">="&A32,Cases!$E$6:$E$1205,"<"&A32+7) -> 91 | C32: =COUNTIFS(Cases!$G$6:$G$1205,">="&A32,Cases!$G$6:$G$1205,"<"&A32+7) -> 73 | D32: =COUNTIF(Cases!$E$6:$E$1205,"<"&A32+7)-COUNTIFS(Cases!$G$6:$G$1205,">=1",Cases!$G$6:$G$1205,"<"&A32+7) -> 226
A33: 46265 | B33: =COUNTIFS(Cases!$E$6:$E$1205,">="&A33,Cases!$E$6:$E$1205,"<"&A33+7) -> 94 | C33: =COUNTIFS(Cases!$G$6:$G$1205,">="&A33,Cases!$G$6:$G$1205,"<"&A33+7) -> 82 | D33: =COUNTIF(Cases!$E$6:$E$1205,"<"&A33+7)-COUNTIFS(Cases!$G$6:$G$1205,">=1",Cases!$G$6:$G$1205,"<"&A33+7) -> 238
A34: 46272 | B34: =COUNTIFS(Cases!$E$6:$E$1205,">="&A34,Cases!$E$6:$E$1205,"<"&A34+7) -> 97 | C34: =COUNTIFS(Cases!$G$6:$G$1205,">="&A34,Cases!$G$6:$G$1205,"<"&A34+7) -> 88 | D34: =COUNTIF(Cases!$E$6:$E$1205,"<"&A34+7)-COUNTIFS(Cases!$G$6:$G$1205,">=1",Cases!$G$6:$G$1205,"<"&A34+7) -> 247
A35: 46279 | B35: =COUNTIFS(Cases!$E$6:$E$1205,">="&A35,Cases!$E$6:$E$1205,"<"&A35+7) -> 99 | C35: =COUNTIFS(Cases!$G$6:$G$1205,">="&A35,Cases!$G$6:$G$1205,"<"&A35+7) -> 80 | D35: =COUNTIF(Cases!$E$6:$E$1205,"<"&A35+7)-COUNTIFS(Cases!$G$6:$G$1205,">=1",Cases!$G$6:$G$1205,"<"&A35+7) -> 266
A38: Month / coverage | B38: Opened | C38: Closed | D38: Closing backlog | E38: Partial month?
A39: Jun 29-30 | B39: 29 | C39: 1 | D39: 28 | E39: Yes
A40: Jul 01-31 | B40: 456 | C40: 313 | D40: 171 | E40: No
A41: Aug 01-31 | B41: 442 | C41: 383 | D41: 230 | E41: No
A42: Sep 01-20 | B42: 273 | C42: 237 | D42: 266 | E42: Yes
A44: Monthly figures are validated MySQL outputs. June and September are partial months and should not be compared directly with full months. Weekly rows are complete seven-day periods.
A48: Refresh: rerun the Python validation/query pipeline, then rebuild this workbook. Tables support filtering; native Pivot is on its own tab. This file is not connected to live systems and has no deployed scheduler or email delivery.

Sheet Pivot
A1: Case volume by department
A3: Counts of all 1,200 cases. Use the PivotTable field list to rearrange Department and Category in desktop Excel. The current layout counts Case ID by Department.
A6: Department | B6: Case count | D6: Source: Cases!A5:C1205. Native Pivot cache contains Department, Category and Case ID. After source edits, Refresh the PivotTable. If source row count changes, rebuild this workbook to extend the cache range.
A7: Customer Services | B7: 500
A8: Warehouse | B8: 341
A9: Installation | B9: 359
A10: Grand Total | B10: 1200
A14: Refresh after source edits. The PivotTable counts all cases in the extract; dashboard status measures use the snapshot cutoff. Calculation and cache checks are documented in the project README. Native Excel Desktop refresh remains unverified.
D20: Chart source / week | E20: Closing backlog
D21: 29 Jun | E21: =Reporting!D24 -> 82
D22: 06 Jul | E22: =Reporting!D25 -> 135
D23: 13 Jul | E23: =Reporting!D26 -> 147
D24: 20 Jul | E24: =Reporting!D27 -> 156
D25: 27 Jul | E25: =Reporting!D28 -> 180
D26: 03 Aug | E26: =Reporting!D29 -> 171
D27: 10 Aug | E27: =Reporting!D30 -> 170
D28: 17 Aug | E28: =Reporting!D31 -> 208
D29: 24 Aug | E29: =Reporting!D32 -> 226
D30: 31 Aug | E30: =Reporting!D33 -> 238
D31: 07 Sept | E31: =Reporting!D34 -> 247
D32: 14 Sept | E32: =Reporting!D35 -> 266

Sheet Cases
A1: Operational case register
A3: One row per case. A:H are inputs; I:O are formula-derived. Blank Closed = still open. Dates are UTC. Filters do not change headline KPIs.
A5: Case ID | B5: Department | C5: Category | D5: Priority | E5: Opened | F5: Due | G5: Closed | H5: Dept ID | I5: Open flag | J5: Overdue flag | K5: Due flag | L5: On-time flag | M5: Closed flag | N5: Resolution days | O5: Status
A6: CASE-00001 | B6: Customer Services | C6: Missing evidence | D6: High | E6: 46234.375 | F6: 46237.375 | G6: 46251.375 | H6: 1 | I6: =IF(AND(E6<Reporting!$B$4,OR(G6="",G6>=Reporting!$B$4)),1,0) -> 0 | J6: =IF(AND(I6=1,F6<Reporting!$B$4),1,0) -> 0 | K6: =IF(F6<Reporting!$B$4,1,0) -> 1 | L6: =IF(AND(K6=1,G6<>"",G6<=F6),1,0) -> 0 | M6: =IF(AND(G6<>"",G6<Reporting!$B$4),1,0) -> 1 | N6: =IF(M6=1,G6-E6,"") -> 17 | O6: =IF(E6>=Reporting!$B$4,"Outside cutoff",IF(M6=1,"Closed",IF(J6=1,"Overdue","Open - within SLA"))) -> Closed
A7: CASE-00002 | B7: Installation | C7: Record mismatch | D7: Medium | E7: 46230.583 | F7: 46237.583 | G7: 46242.583 | H7: 3 | I7: =IF(AND(E7<Reporting!$B$4,OR(G7="",G7>=Reporting!$B$4)),1,0) -> 0 | J7: =IF(AND(I7=1,F7<Reporting!$B$4),1,0) -> 0 | K7: =IF(F7<Reporting!$B$4,1,0) -> 1 | L7: =IF(AND(K7=1,G7<>"",G7<=F7),1,0) -> 0 | M7: =IF(AND(G7<>"",G7<Reporting!$B$4),1,0) -> 1 | N7: =IF(M7=1,G7-E7,"") -> 12 | O7: =IF(E7>=Reporting!$B$4,"Outside cutoff",IF(M7=1,"Closed",IF(J7=1,"Overdue","Open - within SLA"))) -> Closed
A8: CASE-00003 | B8: Customer Services | C8: Record mismatch | D8: High | E8: 46230.5 | F8: 46233.5 | G8: 46233.5 | H8: 1 | I8: =IF(AND(E8<Reporting!$B$4,OR(G8="",G8>=Reporting!$B$4)),1,0) -> 0 | J8: =IF(AND(I8=1,F8<Reporting!$B$4),1,0) -> 0 | K8: =IF(F8<Reporting!$B$4,1,0) -> 1 | L8: =IF(AND(K8=1,G8<>"",G8<=F8),1,0) -> 1 | M8: =IF(AND(G8<>"",G8<Reporting!$B$4),1,0) -> 1 | N8: =IF(M8=1,G8-E8,"") -> 3 | O8: =IF(E8>=Reporting!$B$4,"Outside cutoff",IF(M8=1,"Closed",IF(J8=1,"Overdue","Open - within SLA"))) -> Closed
A9: CASE-00004 | B9: Customer Services | C9: Record mismatch | D9: Low | E9: 46210.625 | F9: 46224.625 | G9: 46223.625 | H9: 1 | I9: =IF(AND(E9<Reporting!$B$4,OR(G9="",G9>=Reporting!$B$4)),1,0) -> 0 | J9: =IF(AND(I9=1,F9<Reporting!$B$4),1,0) -> 0 | K9: =IF(F9<Reporting!$B$4,1,0) -> 1 | L9: =IF(AND(K9=1,G9<>"",G9<=F9),1,0) -> 1 | M9: =IF(AND(G9<>"",G9<Reporting!$B$4),1,0) -> 1 | N9: =IF(M9=1,G9-E9,"") -> 13 | O9: =IF(E9>=Reporting!$B$4,"Outside cutoff",IF(M9=1,"Closed",IF(J9=1,"Overdue","Open - within SLA"))) -> Closed
A10: CASE-00005 | B10: Installation | C10: Late review | D10: High | E10: 46245.667 | F10: 46248.667 | G10: 46257.667 | H10: 3 | I10: =IF(AND(E10<Reporting!$B$4,OR(G10="",G10>=Reporting!$B$4)),1,0) -> 0 | J10: =IF(AND(I10=1,F10<Reporting!$B$4),1,0) -> 0 | K10: =IF(F10<Reporting!$B$4,1,0) -> 1 | L10: =IF(AND(K10=1,G10<>"",G10<=F10),1,0) -> 0 | M10: =IF(AND(G10<>"",G10<Reporting!$B$4),1,0) -> 1 | N10: =IF(M10=1,G10-E10,"") -> 12 | O10: =IF(E10>=Reporting!$B$4,"Outside cutoff",IF(M10=1,"Closed",IF(J10=1,"Overdue","Open - within SLA"))) -> Closed
A11: CASE-00006 | B11: Customer Services | C11: Process deviation | D11: Medium | E11: 46223.417 | F11: 46230.417 | G11: 46240.5 | H11: 1 | I11: =IF(AND(E11<Reporting!$B$4,OR(G11="",G11>=Reporting!$B$4)),1,0) -> 0 | J11: =IF(AND(I11=1,F11<Reporting!$B$4),1,0) -> 0 | K11: =IF(F11<Reporting!$B$4,1,0) -> 1 | L11: =IF(AND(K11=1,G11<>"",G11<=F11),1,0) -> 0 | M11: =IF(AND(G11<>"",G11<Reporting!$B$4),1,0) -> 1 | N11: =IF(M11=1,G11-E11,"") -> 17.083333 | O11: =IF(E11>=Reporting!$B$4,"Outside cutoff",IF(M11=1,"Closed",IF(J11=1,"Overdue","Open - within SLA"))) -> Closed
A12: CASE-00007 | B12: Customer Services | C12: Late review | D12: Medium | E12: 46227.458 | F12: 46234.458 | G12: 46232.458 | H12: 1 | I12: =IF(AND(E12<Reporting!$B$4,OR(G12="",G12>=Reporting!$B$4)),1,0) -> 0 | J12: =IF(AND(I12=1,F12<Reporting!$B$4),1,0) -> 0 | K12: =IF(F12<Reporting!$B$4,1,0) -> 1 | L12: =IF(AND(K12=1,G12<>"",G12<=F12),1,0) -> 1 | M12: =IF(AND(G12<>"",G12<Reporting!$B$4),1,0) -> 1 | N12: =IF(M12=1,G12-E12,"") -> 5 | O12: =IF(E12>=Reporting!$B$4,"Outside cutoff",IF(M12=1,"Closed",IF(J12=1,"Overdue","Open - within SLA"))) -> Closed
A13: CASE-00008 | B13: Warehouse | C13: Process deviation | D13: Medium | E13: 46254.542 | F13: 46261.542 | G13: 46276.625 | H13: 2 | I13: =IF(AND(E13<Reporting!$B$4,OR(G13="",G13>=Reporting!$B$4)),1,0) -> 0 | J13: =IF(AND(I13=1,F13<Reporting!$B$4),1,0) -> 0 | K13: =IF(F13<Reporting!$B$4,1,0) -> 1 | L13: =IF(AND(K13=1,G13<>"",G13<=F13),1,0) -> 0 | M13: =IF(AND(G13<>"",G13<Reporting!$B$4),1,0) -> 1 | N13: =IF(M13=1,G13-E13,"") -> 22.083333 | O13: =IF(E13>=Reporting!$B$4,"Outside cutoff",IF(M13=1,"Closed",IF(J13=1,"Overdue","Open - within SLA"))) -> Closed
A14: CASE-00009 | B14: Installation | C14: Late review | D14: Medium | E14: 46233.542 | F14: 46240.542 | G14: 46247.583 | H14: 3 | I14: =IF(AND(E14<Reporting!$B$4,OR(G14="",G14>=Reporting!$B$4)),1,0) -> 0 | J14: =IF(AND(I14=1,F14<Reporting!$B$4),1,0) -> 0 | K14: =IF(F14<Reporting!$B$4,1,0) -> 1 | L14: =IF(AND(K14=1,G14<>"",G14<=F14),1,0) -> 0 | M14: =IF(AND(G14<>"",G14<Reporting!$B$4),1,0) -> 1 | N14: =IF(M14=1,G14-E14,"") -> 14.041667 | O14: =IF(E14>=Reporting!$B$4,"Outside cutoff",IF(M14=1,"Closed",IF(J14=1,"Overdue","Open - within SLA"))) -> Closed
A15: CASE-00010 | B15: Customer Services | C15: Record mismatch | D15: Medium | E15: 46261.542 | F15: 46268.542 | H15: 1 | I15: =IF(AND(E15<Reporting!$B$4,OR(G15="",G15>=Reporting!$B$4)),1,0) -> 1 | J15: =IF(AND(I15=1,F15<Reporting!$B$4),1,0) -> 1 | K15: =IF(F15<Reporting!$B$4,1,0) -> 1 | L15: =IF(AND(K15=1,G15<>"",G15<=F15),1,0) -> 0 | M15: =IF(AND(G15<>"",G15<Reporting!$B$4),1,0) -> 0 | N15: =IF(M15=1,G15-E15,"") | O15: =IF(E15>=Reporting!$B$4,"Outside cutoff",IF(M15=1,"Closed",IF(J15=1,"Overdue","Open - within SLA"))) -> Overdue
A16: CASE-00011 | B16: Customer Services | C16: Process deviation | D16: High | E16: 46257.5 | F16: 46260.5 | G16: 46270.542 | H16: 1 | I16: =IF(AND(E16<Reporting!$B$4,OR(G16="",G16>=Reporting!$B$4)),1,0) -> 0 | J16: =IF(AND(I16=1,F16<Reporting!$B$4),1,0) -> 0 | K16: =IF(F16<Reporting!$B$4,1,0) -> 1 | L16: =IF(AND(K16=1,G16<>"",G16<=F16),1,0) -> 0 | M16: =IF(AND(G16<>"",G16<Reporting!$B$4),1,0) -> 1 | N16: =IF(M16=1,G16-E16,"") -> 13.041667 | O16: =IF(E16>=Reporting!$B$4,"Outside cutoff",IF(M16=1,"Closed",IF(J16=1,"Overdue","Open - within SLA"))) -> Closed
A17: CASE-00012 | B17: Warehouse | C17: Record mismatch | D17: Medium | E17: 46247.583 | F17: 46254.583 | G17: 46274.583 | H17: 2 | I17: =IF(AND(E17<Reporting!$B$4,OR(G17="",G17>=Reporting!$B$4)),1,0) -> 0 | J17: =IF(AND(I17=1,F17<Reporting!$B$4),1,0) -> 0 | K17: =IF(F17<Reporting!$B$4,1,0) -> 1 | L17: =IF(AND(K17=1,G17<>"",G17<=F17),1,0) -> 0 | M17: =IF(AND(G17<>"",G17<Reporting!$B$4),1,0) -> 1 | N17: =IF(M17=1,G17-E17,"") -> 27 | O17: =IF(E17>=Reporting!$B$4,"Outside cutoff",IF(M17=1,"Closed",IF(J17=1,"Overdue","Open - within SLA"))) -> Closed
A18: CASE-00013 | B18: Customer Services | C18: Late review | D18: Medium | E18: 46242.417 | F18: 46249.417 | G18: 46258.417 | H18: 1 | I18: =IF(AND(E18<Reporting!$B$4,OR(G18="",G18>=Reporting!$B$4)),1,0) -> 0 | J18: =IF(AND(I18=1,F18<Reporting!$B$4),1,0) -> 0 | K18: =IF(F18<Reporting!$B$4,1,0) -> 1 | L18: =IF(AND(K18=1,G18<>"",G18<=F18),1,0) -> 0 | M18: =IF(AND(G18<>"",G18<Reporting!$B$4),1,0) -> 1 | N18: =IF(M18=1,G18-E18,"") -> 16 | O18: =IF(E18>=Reporting!$B$4,"Outside cutoff",IF(M18=1,"Closed",IF(J18=1,"Overdue","Open - within SLA"))) -> Closed
A19: CASE-00014 | B19: Customer Services | C19: Record mismatch | D19: Medium | E19: 46220.542 | F19: 46227.542 | G19: 46236.542 | H19: 1 | I19: =IF(AND(E19<Reporting!$B$4,OR(G19="",G19>=Reporting!$B$4)),1,0) -> 0 | J19: =IF(AND(I19=1,F19<Reporting!$B$4),1,0) -> 0 | K19: =IF(F19<Reporting!$B$4,1,0) -> 1 | L19: =IF(AND(K19=1,G19<>"",G19<=F19),1,0) -> 0 | M19: =IF(AND(G19<>"",G19<Reporting!$B$4),1,0) -> 1 | N19: =IF(M19=1,G19-E19,"") -> 16 | O19: =IF(E19>=Reporting!$B$4,"Outside cutoff",IF(M19=1,"Closed",IF(J19=1,"Overdue","Open - within SLA"))) -> Closed
A20: CASE-00015 | B20: Customer Services | C20: Record mismatch | D20: Low | E20: 46239.375 | F20: 46253.375 | G20: 46241.375 | H20: 1 | I20: =IF(AND(E20<Reporting!$B$4,OR(G20="",G20>=Reporting!$B$4)),1,0) -> 0 | J20: =IF(AND(I20=1,F20<Reporting!$B$4),1,0) -> 0 | K20: =IF(F20<Reporting!$B$4,1,0) -> 1 | L20: =IF(AND(K20=1,G20<>"",G20<=F20),1,0) -> 1 | M20: =IF(AND(G20<>"",G20<Reporting!$B$4),1,0) -> 1 | N20: =IF(M20=1,G20-E20,"") -> 2 | O20: =IF(E20>=Reporting!$B$4,"Outside cutoff",IF(M20=1,"Closed",IF(J20=1,"Overdue","Open - within SLA"))) -> Closed
A21: CASE-00016 | B21: Customer Services | C21: Missing evidence | D21: Medium | E21: 46268.375 | F21: 46275.375 | G21: 46269.417 | H21: 1 | I21: =IF(AND(E21<Reporting!$B$4,OR(G21="",G21>=Reporting!$B$4)),1,0) -> 0 | J21: =IF(AND(I21=1,F21<Reporting!$B$4),1,0) -> 0 | K21: =IF(F21<Reporting!$B$4,1,0) -> 1 | L21: =IF(AND(K21=1,G21<>"",G21<=F21),1,0) -> 1 | M21: =IF(AND(G21<>"",G21<Reporting!$B$4),1,0) -> 1 | N21: =IF(M21=1,G21-E21,"") -> 1.0416667 | O21: =IF(E21>=Reporting!$B$4,"Outside cutoff",IF(M21=1,"Closed",IF(J21=1,"Overdue","Open - within SLA"))) -> Closed
A22: CASE-00017 | B22: Customer Services | C22: Missing evidence | D22: Medium | E22: 46229.625 | F22: 46236.625 | G22: 46237.667 | H22: 1 | I22: =IF(AND(E22<Reporting!$B$4,OR(G22="",G22>=Reporting!$B$4)),1,0) -> 0 | J22: =IF(AND(I22=1,F22<Reporting!$B$4),1,0) -> 0 | K22: =IF(F22<Reporting!$B$4,1,0) -> 1 | L22: =IF(AND(K22=1,G22<>"",G22<=F22),1,0) -> 0 | M22: =IF(AND(G22<>"",G22<Reporting!$B$4),1,0) -> 1 | N22: =IF(M22=1,G22-E22,"") -> 8.0416667 | O22: =IF(E22>=Reporting!$B$4,"Outside cutoff",IF(M22=1,"Closed",IF(J22=1,"Overdue","Open - within SLA"))) -> Closed
A23: CASE-00018 | B23: Warehouse | C23: Record mismatch | D23: Medium | E23: 46264.625 | F23: 46271.625 | G23: 46275.667 | H23: 2 | I23: =IF(AND(E23<Reporting!$B$4,OR(G23="",G23>=Reporting!$B$4)),1,0) -> 0 | J23: =IF(AND(I23=1,F23<Reporting!$B$4),1,0) -> 0 | K23: =IF(F23<Reporting!$B$4,1,0) -> 1 | L23: =IF(AND(K23=1,G23<>"",G23<=F23),1,0) -> 0 | M23: =IF(AND(G23<>"",G23<Reporting!$B$4),1,0) -> 1 | N23: =IF(M23=1,G23-E23,"") -> 11.041667 | O23: =IF(E23>=Reporting!$B$4,"Outside cutoff",IF(M23=1,"Closed",IF(J23=1,"Overdue","Open - within SLA"))) -> Closed
A24: CASE-00019 | B24: Warehouse | C24: Process deviation | D24: Medium | E24: 46258.583 | F24: 46265.583 | G24: 46283.583 | H24: 2 | I24: =IF(AND(E24<Reporting!$B$4,OR(G24="",G24>=Reporting!$B$4)),1,0) -> 0 | J24: =IF(AND(I24=1,F24<Reporting!$B$4),1,0) -> 0 | K24: =IF(F24<Reporting!$B$4,1,0) -> 1 | L24: =IF(AND(K24=1,G24<>"",G24<=F24),1,0) -> 0 | M24: =IF(AND(G24<>"",G24<Reporting!$B$4),1,0) -> 1 | N24: =IF(M24=1,G24-E24,"") -> 25 | O24: =IF(E24>=Reporting!$B$4,"Outside cutoff",IF(M24=1,"Closed",IF(J24=1,"Overdue","Open - within SLA"))) -> Closed
A25: CASE-00020 | B25: Warehouse | C25: Missing evidence | D25: Low | E25: 46285.375 | F25: 46299.375 | H25: 2 | I25: =IF(AND(E25<Reporting!$B$4,OR(G25="",G25>=Reporting!$B$4)),1,0) -> 1 | J25: =IF(AND(I25=1,F25<Reporting!$B$4),1,0) -> 0 | K25: =IF(F25<Reporting!$B$4,1,0) -> 0 | L25: =IF(AND(K25=1,G25<>"",G25<=F25),1,0) -> 0 | M25: =IF(AND(G25<>"",G25<Reporting!$B$4),1,0) -> 0 | N25: =IF(M25=1,G25-E25,"") | O25: =IF(E25>=Reporting!$B$4,"Outside cutoff",IF(M25=1,"Closed",IF(J25=1,"Overdue","Open - within SLA"))) -> Open - within SLA
A26: CASE-00021 | B26: Installation | C26: Process deviation | D26: Medium | E26: 46250.458 | F26: 46257.458 | G26: 46256.542 | H26: 3 | I26: =IF(AND(E26<Reporting!$B$4,OR(G26="",G26>=Reporting!$B$4)),1,0) -> 0 | J26: =IF(AND(I26=1,F26<Reporting!$B$4),1,0) -> 0 | K26: =IF(F26<Reporting!$B$4,1,0) -> 1 | L26: =IF(AND(K26=1,G26<>"",G26<=F26),1,0) -> 1 | M26: =IF(AND(G26<>"",G26<Reporting!$B$4),1,0) -> 1 | N26: =IF(M26=1,G26-E26,"") -> 6.0833333 | O26: =IF(E26>=Reporting!$B$4,"Outside cutoff",IF(M26=1,"Closed",IF(J26=1,"Overdue","Open - within SLA"))) -> Closed
A27: CASE-00022 | B27: Customer Services | C27: Late review | D27: Medium | E27: 46218.417 | F27: 46225.417 | G27: 46223.458 | H27: 1 | I27: =IF(AND(E27<Reporting!$B$4,OR(G27="",G27>=Reporting!$B$4)),1,0) -> 0 | J27: =IF(AND(I27=1,F27<Reporting!$B$4),1,0) -> 0 | K27: =IF(F27<Reporting!$B$4,1,0) -> 1 | L27: =IF(AND(K27=1,G27<>"",G27<=F27),1,0) -> 1 | M27: =IF(AND(G27<>"",G27<Reporting!$B$4),1,0) -> 1 | N27: =IF(M27=1,G27-E27,"") -> 5.0416667 | O27: =IF(E27>=Reporting!$B$4,"Outside cutoff",IF(M27=1,"Closed",IF(J27=1,"Overdue","Open - within SLA"))) -> Closed
A28: CASE-00023 | B28: Customer Services | C28: Record mismatch | D28: Medium | E28: 46235.333 | F28: 46242.333 | G28: 46251.333 | H28: 1 | I28: =IF(AND(E28<Reporting!$B$4,OR(G28="",G28>=Reporting!$B$4)),1,0) -> 0 | J28: =IF(AND(I28=1,F28<Reporting!$B$4),1,0) -> 0 | K28: =IF(F28<Reporting!$B$4,1,0) -> 1 | L28: =IF(AND(K28=1,G28<>"",G28<=F28),1,0) -> 0 | M28: =IF(AND(G28<>"",G28<Reporting!$B$4),1,0) -> 1 | N28: =IF(M28=1,G28-E28,"") -> 16 | O28: =IF(E28>=Reporting!$B$4,"Outside cutoff",IF(M28=1,"Closed",IF(J28=1,"Overdue","Open - within SLA"))) -> Closed
A29: CASE-00024 | B29: Customer Services | C29: Missing evidence | D29: Low | E29: 46275.667 | F29: 46289.667 | H29: 1 | I29: =IF(AND(E29<Reporting!$B$4,OR(G29="",G29>=Reporting!$B$4)),1,0) -> 1 | J29: =IF(AND(I29=1,F29<Reporting!$B$4),1,0) -> 0 | K29: =IF(F29<Reporting!$B$4,1,0) -> 0 | L29: =IF(AND(K29=1,G29<>"",G29<=F29),1,0) -> 0 | M29: =IF(AND(G29<>"",G29<Reporting!$B$4),1,0) -> 0 | N29: =IF(M29=1,G29-E29,"") | O29: =IF(E29>=Reporting!$B$4,"Outside cutoff",IF(M29=1,"Closed",IF(J29=1,"Overdue","Open - within SLA"))) -> Open - within SLA
A30: CASE-00025 | B30: Installation | C30: Missing evidence | D30: Medium | E30: 46268.375 | F30: 46275.375 | G30: 46277.375 | H30: 3 | I30: =IF(AND(E30<Reporting!$B$4,OR(G30="",G30>=Reporting!$B$4)),1,0) -> 0 | J30: =IF(AND(I30=1,F30<Reporting!$B$4),1,0) -> 0 | K30: =IF(F30<Reporting!$B$4,1,0) -> 1 | L30: =IF(AND(K30=1,G30<>"",G30<=F30),1,0) -> 0 | M30: =IF(AND(G30<>"",G30<Reporting!$B$4),1,0) -> 1 | N30: =IF(M30=1,G30-E30,"") -> 9 | O30: =IF(E30>=Reporting!$B$4,"Outside cutoff",IF(M30=1,"Closed",IF(J30=1,"Overdue","Open - within SLA"))) -> Closed
A31: CASE-00026 | B31: Customer Services | C31: Late review | D31: Medium | E31: 46245.542 | F31: 46252.542 | H31: 1 | I31: =IF(AND(E31<Reporting!$B$4,OR(G31="",G31>=Reporting!$B$4)),1,0) -> 1 | J31: =IF(AND(I31=1,F31<Reporting!$B$4),1,0) -> 1 | K31: =IF(F31<Reporting!$B$4,1,0) -> 1 | L31: =IF(AND(K31=1,G31<>"",G31<=F31),1,0) -> 0 | M31: =IF(AND(G31<>"",G31<Reporting!$B$4),1,0) -> 0 | N31: =IF(M31=1,G31-E31,"") | O31: =IF(E31>=Reporting!$B$4,"Outside cutoff",IF(M31=1,"Closed",IF(J31=1,"Overdue","Open - within SLA"))) -> Overdue
A32: CASE-00027 | B32: Customer Services | C32: Record mismatch | D32: Medium | E32: 46202.333 | F32: 46209.333 | G32: 46203.333 | H32: 1 | I32: =IF(AND(E32<Reporting!$B$4,OR(G32="",G32>=Reporting!$B$4)),1,0) -> 0 | J32: =IF(AND(I32=1,F32<Reporting!$B$4),1,0) -> 0 | K32: =IF(F32<Reporting!$B$4,1,0) -> 1 | L32: =IF(AND(K32=1,G32<>"",G32<=F32),1,0) -> 1 | M32: =IF(AND(G32<>"",G32<Reporting!$B$4),1,0) -> 1 | N32: =IF(M32=1,G32-E32,"") -> 1 | O32: =IF(E32>=Reporting!$B$4,"Outside cutoff",IF(M32=1,"Closed",IF(J32=1,"Overdue","Open - within SLA"))) -> Closed
A33: CASE-00028 | B33: Customer Services | C33: Process deviation | D33: Low | E33: 46215.333 | F33: 46229.333 | G33: 46231.417 | H33: 1 | I33: =IF(AND(E33<Reporting!$B$4,OR(G33="",G33>=Reporting!$B$4)),1,0) -> 0 | J33: =IF(AND(I33=1,F33<Reporting!$B$4),1,0) -> 0 | K33: =IF(F33<Reporting!$B$4,1,0) -> 1 | L33: =IF(AND(K33=1,G33<>"",G33<=F33),1,0) -> 0 | M33: =IF(AND(G33<>"",G33<Reporting!$B$4),1,0) -> 1 | N33: =IF(M33=1,G33-E33,"") -> 16.083333 | O33: =IF(E33>=Reporting!$B$4,"Outside cutoff",IF(M33=1,"Closed",IF(J33=1,"Overdue","Open - within SLA"))) -> Closed
A34: CASE-00029 | B34: Installation | C34: Late review | D34: Medium | E34: 46273.583 | F34: 46280.583 | G34: 46280.625 | H34: 3 | I34: =IF(AND(E34<Reporting!$B$4,OR(G34="",G34>=Reporting!$B$4)),1,0) -> 0 | J34: =IF(AND(I34=1,F34<Reporting!$B$4),1,0) -> 0 | K34: =IF(F34<Reporting!$B$4,1,0) -> 1 | L34: =IF(AND(K34=1,G34<>"",G34<=F34),1,0) -> 0 | M34: =IF(AND(G34<>"",G34<Reporting!$B$4),1,0) -> 1 | N34: =IF(M34=1,G34-E34,"") -> 7.0416667 | O34: =IF(E34>=Reporting!$B$4,"Outside cutoff",IF(M34=1,"Closed",IF(J34=1,"Overdue","Open - within SLA"))) -> Closed
A35: CASE-00030 | B35: Customer Services | C35: Late review | D35: High | E35: 46222.667 | F35: 46225.667 | G35: 46236.708 | H35: 1 | I35: =IF(AND(E35<Reporting!$B$4,OR(G35="",G35>=Reporting!$B$4)),1,0) -> 0 | J35: =IF(AND(I35=1,F35<Reporting!$B$4),1,0) -> 0 | K35: =IF(F35<Reporting!$B$4,1,0) -> 1 | L35: =IF(AND(K35=1,G35<>"",G35<=F35),1,0) -> 0 | M35: =IF(AND(G35<>"",G35<Reporting!$B$4),1,0) -> 1 | N35: =IF(M35=1,G35-E35,"") -> 14.041667 | O35: =IF(E35>=Reporting!$B$4,"Outside cutoff",IF(M35=1,"Closed",IF(J35=1,"Overdue","Open - within SLA"))) -> Closed
A36: CASE-00031 | B36: Installation | C36: Late review | D36: Low | E36: 46282.5 | F36: 46296.5 | H36: 3 | I36: =IF(AND(E36<Reporting!$B$4,OR(G36="",G36>=Reporting!$B$4)),1,0) -> 1 | J36: =IF(AND(I36=1,F36<Reporting!$B$4),1,0) -> 0 | K36: =IF(F36<Reporting!$B$4,1,0) -> 0 | L36: =IF(AND(K36=1,G36<>"",G36<=F36),1,0) -> 0 | M36: =IF(AND(G36<>"",G36<Reporting!$B$4),1,0) -> 0 | N36: =IF(M36=1,G36-E36,"") | O36: =IF(E36>=Reporting!$B$4,"Outside cutoff",IF(M36=1,"Closed",IF(J36=1,"Overdue","Open - within SLA"))) -> Open - within SLA
A37: CASE-00032 | B37: Customer Services | C37: Missing evidence | D37: Medium | E37: 46221.667 | F37: 46228.667 | G37: 46225.708 | H37: 1 | I37: =IF(AND(E37<Reporting!$B$4,OR(G37="",G37>=Reporting!$B$4)),1,0) -> 0 | J37: =IF(AND(I37=1,F37<Reporting!$B$4),1,0) -> 0 | K37: =IF(F37<Reporting!$B$4,1,0) -> 1 | L37: =IF(AND(K37=1,G37<>"",G37<=F37),1,0) -> 1 | M37: =IF(AND(G37<>"",G37<Reporting!$B$4),1,0) -> 1 | N37: =IF(M37=1,G37-E37,"") -> 4.0416667 | O37: =IF(E37>=Reporting!$B$4,"Outside cutoff",IF(M37=1,"Closed",IF(J37=1,"Overdue","Open - within SLA"))) -> Closed
A38: CASE-00033 | B38: Installation | C38: Late review | D38: High | E38: 46222.542 | F38: 46225.542 | G38: 46237.542 | H38: 3 | I38: =IF(AND(E38<Reporting!$B$4,OR(G38="",G38>=Reporting!$B$4)),1,0) -> 0 | J38: =IF(AND(I38=1,F38<Reporting!$B$4),1,0) -> 0 | K38: =IF(F38<Reporting!$B$4,1,0) -> 1 | L38: =IF(AND(K38=1,G38<>"",G38<=F38),1,0) -> 0 | M38: =IF(AND(G38<>"",G38<Reporting!$B$4),1,0) -> 1 | N38: =IF(M38=1,G38-E38,"") -> 15 | O38: =IF(E38>=Reporting!$B$4,"Outside cutoff",IF(M38=1,"Closed",IF(J38=1,"Overdue","Open - within SLA"))) -> Closed
A39: CASE-00034 | B39: Customer Services | C39: Record mismatch | D39: Low | E39: 46212.458 | F39: 46226.458 | G39: 46218.5 | H39: 1 | I39: =IF(AND(E39<Reporting!$B$4,OR(G39="",G39>=Reporting!$B$4)),1,0) -> 0 | J39: =IF(AND(I39=1,F39<Reporting!$B$4),1,0) -> 0 | K39: =IF(F39<Reporting!$B$4,1,0) -> 1 | L39: =IF(AND(K39=1,G39<>"",G39<=F39),1,0) -> 1 | M39: =IF(AND(G39<>"",G39<Reporting!$B$4),1,0) -> 1 | N39: =IF(M39=1,G39-E39,"") -> 6.0416667 | O39: =IF(E39>=Reporting!$B$4,"Outside cutoff",IF(M39=1,"Closed",IF(J39=1,"Overdue","Open - within SLA"))) -> Closed
A40: CASE-00035 | B40: Customer Services | C40: Missing evidence | D40: High | E40: 46207.583 | F40: 46210.583 | G40: 46225.625 | H40: 1 | I40: =IF(AND(E40<Reporting!$B$4,OR(G40="",G40>=Reporting!$B$4)),1,0) -> 0 | J40: =IF(AND(I40=1,F40<Reporting!$B$4),1,0) -> 0 | K40: =IF(F40<Reporting!$B$4,1,0) -> 1 | L40: =IF(AND(K40=1,G40<>"",G40<=F40),1,0) -> 0 | M40: =IF(AND(G40<>"",G40<Reporting!$B$4),1,0) -> 1 | N40: =IF(M40=1,G40-E40,"") -> 18.041667 | O40: =IF(E40>=Reporting!$B$4,"Outside cutoff",IF(M40=1,"Closed",IF(J40=1,"Overdue","Open - within SLA"))) -> Closed
A41: CASE-00036 | B41: Customer Services | C41: Late review | D41: Low | E41: 46231.667 | F41: 46245.667 | G41: 46232.667 | H41: 1 | I41: =IF(AND(E41<Reporting!$B$4,OR(G41="",G41>=Reporting!$B$4)),1,0) -> 0 | J41: =IF(AND(I41=1,F41<Reporting!$B$4),1,0) -> 0 | K41: =IF(F41<Reporting!$B$4,1,0) -> 1 | L41: =IF(AND(K41=1,G41<>"",G41<=F41),1,0) -> 1 | M41: =IF(AND(G41<>"",G41<Reporting!$B$4),1,0) -> 1 | N41: =IF(M41=1,G41-E41,"") -> 1 | O41: =IF(E41>=Reporting!$B$4,"Outside cutoff",IF(M41=1,"Closed",IF(J41=1,"Overdue","Open - within SLA"))) -> Closed
A42: CASE-00037 | B42: Warehouse | C42: Process deviation | D42: Low | E42: 46257.333 | F42: 46271.333 | G42: 46271.375 | H42: 2 | I42: =IF(AND(E42<Reporting!$B$4,OR(G42="",G42>=Reporting!$B$4)),1,0) -> 0 | J42: =IF(AND(I42=1,F42<Reporting!$B$4),1,0) -> 0 | K42: =IF(F42<Reporting!$B$4,1,0) -> 1 | L42: =IF(AND(K42=1,G42<>"",G42<=F42),1,0) -> 0 | M42: =IF(AND(G42<>"",G42<Reporting!$B$4),1,0) -> 1 | N42: =IF(M42=1,G42-E42,"") -> 14.041667 | O42: =IF(E42>=Reporting!$B$4,"Outside cutoff",IF(M42=1,"Closed",IF(J42=1,"Overdue","Open - within SLA"))) -> Closed
...

Sheet Runs
A1: Report freshness and publication controls
A3: Four controlled tests executed on 27 Sep 2026. Evaluation times simulate source freshness and deadlines; these are not historical scheduled runs. Blocked runs preserve the latest successful report.
A6: Scenario | B6: Status | C6: Input rows | D6: Accepted | E6: Issues | F6: Age (min) | G6: Runtime (ms) | H6: Published? | I6: MySQL | J6: Evaluated UTC
A7: clean | B7: ON_TIME | C7: 1200 | D7: 1200 | E7: 0 | F7: 5 | G7: 468 | H7: Yes | I7: 8.4.11 | J7: 46292.416
A8: dirty | B8: BLOCKED_DATA | C8: 1201 | D8: 1194 | E8: 7 | F8: 10 | G8: 3 | H8: No | I8: Not queried | J8: 46292.419
A9: stale | B9: BLOCKED_STALE | C9: 1200 | D9: 1200 | E9: 0 | F9: 60 | G9: 2.9 | H9: No | I9: Not queried | J9: 46292.454
A10: late | B10: LATE | C10: 1200 | D10: 1200 | E10: 0 | F10: 25 | G10: 424.7 | H10: Yes | I10: 8.4.11 | J10: 46292.43
A13: Data checks: unique keys, valid departments/categories/priorities, parseable dates, chronological order and snapshot boundaries. The dirty fixture has 1,201 rows; both duplicate occurrences are rejected, leaving 1,194 acceptable rows. Any data issue blocks publication.
A17: Freshness: source age must be 0-30 minutes. Valid but late runs are labelled LATE and may publish; invalid or stale runs cannot. Source SHA-256 and real execution timestamps are retained in the evidence files. All headline, department and 100 period-row results were reconciled independently.
A21: Production next steps: agree metric definitions with stakeholders, connect an authorised source, configure credentials and scheduling, then test alert delivery, retries and ownership. No scheduler, email transport or production connection is installed in this demonstration.
